<?xml version="1.0" ?>

<robot name="bot" xmlns:xacro="https://www.ros.org/wiki/xacro" >

    <!--Gazebo Differential Drive Plugin-->
    <gazebo>
      <plugin name="differential_drive_controller" filename="libgazebo_ros_diff_drive.so">
        <alwaysOn>true</alwaysOn>
        <!-- Plugin update rate in Hz -->
        <updateRate>40</updateRate>
        <!-- Name of left joint, defaults to `left_joint` -->
        <leftJoint>joint_left_rear_wheel</leftJoint>
        <!-- Name of right joint, defaults to `right_joint` -->
        <rightJoint>joint_right_rear_wheel</rightJoint>
        <!-- The distance from the center of one wheel to the other, in meters, defaults to 0.34 m -->
        <wheelSeparation>3.1414</wheelSeparation>
        <!-- Diameter of the wheels, in meters, defaults to 0.15 m -->
        <wheelDiameter>0.2</wheelDiameter>
         <!-- Maximum torque which the wheels can produce, in Nm, defaults to 5 Nm   ; if doesn't works do wheelTorque-->
        <torque>20</torque>
        <!-- Topic to receive geometry_msgs/Twist message commands, defaults to `cmd_vel` -->
        <commandTopic>cmd_vel</commandTopic>
        <!-- Topic to publish nav_msgs/Odometry messages, defaults to `odom` -->
        <odometryTopic>odom</odometryTopic>
        <!-- Odometry frame, defaults to `odom` -->
        <odometryFrame>odom</odometryFrame>
        <!-- Robot frame to calculate odometry from, defaults to `base_footprint` -->
        <robotBaseFrame>base_footprint</robotBaseFrame>
        <!-- Odometry source, 0 for ENCODER, 1 for WORLD, defaults to WORLD -->
        <odometrySource>1</odometrySource>

        <!-- Set to true to publish transforms for the wheel links, defaults to false -->
        <publishWheelTF>true</publishWheelTF>

        <!-- Set to true to publish transforms for the odometry, defaults to true -->
        <publishOdom>true</publishOdom>

        <!-- Set to true to publish sensor_msgs/JointState on /joint_states for the wheel joints, defaults to false -->
        <publishWheelJointState>true</publishWheelJointState>

        <!-- Set to true to swap right and left wheels, defaults to true -->
        <legacyMode>false</legacyMode>
      </plugin>
    </gazebo>


    <gazebo>
        <plugin name="gazebo_ros_control" filename="libgazebo_ros_control.so">
        <robotNamespace>/bot</robotNamespace>
        </plugin>
    </gazebo> 
    <transmission name="tran1">
        <type>transmission_interface/SimpleTransmission</type>
        <joint name="joint_left_rear_wheel">
            <hardwareInterface>EffortJointInterface</hardwareInterface>
        </joint>
        <actuator name="left_rear_motor">
            <hardwareInterface>EffortJointInterface</hardwareInterface>
            <mechanicalReduction>1</mechanicalReduction>
        </actuator>
    </transmission>

    <transmission name="tran2">
        <type>transmission_interface/SimpleTransmission</type>
        <joint name="joint_right_rear_wheel">
            <hardwareInterface>EffortJointInterface</hardwareInterface>
        </joint>
        <actuator name="right_rear_motor">
            <hardwareInterface>EffortJointInterface</hardwareInterface>
            <mechanicalReduction>1</mechanicalReduction>
        </actuator>
    </transmission>

  
    <material name="black">
      <color rgba="0.0 0.0 0.0 1.0"/>
    </material>
    <material name="blue">
      <color rgba="0.203125 0.23828125 0.28515625 1.0"/>
    </material>
    <material name="green">
      <color rgba="0.0 0.8 0.0 1.0"/>
    </material>
    <material name="grey">
      <color rgba="0.2 0.2 0.2 1.0"/>
    </material>
    <material name="orange">
      <color rgba="1.0 0.423529411765 0.0392156862745 1.0"/>
    </material>
    <material name="brown">
      <color rgba="0.870588235294 0.811764705882 0.764705882353 1.0"/>
    </material>
    <material name="red">
      <color rgba="0.80078125 0.12890625 0.1328125 1.0"/>
    </material>
    <material name="white">
      <color rgba="1.0 1.0 1.0 1.0"/>
    </material>  
    
    <gazebo reference="link_chassis">
      <material>Gazebo/Red</material>
    </gazebo>
    <gazebo reference="link_left_front_wheel">
      <material>Gazebo/Black</material>
    </gazebo>
    <gazebo reference="link_right_front_wheel">
      <material>Gazebo/Black</material>
    </gazebo>
    <gazebo reference="link_left_rear_wheel">
      <material>Gazebo/Black</material>
    </gazebo>
    <gazebo reference="link_right_rear_wheel">
      <material>Gazebo/Black</material>
    </gazebo>
      
    <link name="link_chassis">
      <!-- pose and inertial -->
      <pose>0 0 0.1 0 0 0</pose>
      
      <inertial>
        <mass value="5"/>
        <origin rpy="0 0 0" xyz="0 0 0.1"/>
        <inertia ixx="0.0395416666667" ixy="0" ixz="0" iyy="0.106208333333" iyz="0" izz="0.106208333333"/>
      </inertial>
      
      <collision name="collision_chassis">
        <geometry>
          <box size="0.5 0.3 0.03"/>
        </geometry>
      </collision>
      
      <visual>
        <origin rpy="0 0 0" xyz="0 0 0"/>
        <geometry>
          <box size="0.5 0.3 0.07"/>
        </geometry>
        <material name="blue"/>
      </visual>
      
    </link>
    
    <!-- Create front_wheel right -->  
      
    <link name="link_right_front_wheel">    
      <inertial>
        <mass value="0.2"/>
        <origin rpy="0 1.5707 1.5707" xyz="0 0 0"/>
        <inertia ixx="0.00052666666" ixy="0" ixz="0" iyy="0.00052666666" iyz="0" izz="0.001"/>
      </inertial>
      
      <collision name="link_right_front_wheel_collision">
        <origin rpy="0 1.5707 1.5707" xyz="0 0 0" />
        <geometry>
          <cylinder length="0.04" radius="0.1"/>
        </geometry>
      </collision>
      
      <visual name="link_right_front_wheel_visual">
        <origin rpy="0 1.5707 1.5707" xyz="0 0 0"/>
        <geometry>
          <cylinder length="0.04" radius="0.1"/>
        </geometry>      
      </visual>
      
    </link>
      
    <!--   Joint for right front_wheel  -->
    <joint name="joint_right_front_wheel" type="continuous">
      <origin rpy="0 0 0" xyz="0.22 0.18 0"/>
      <child link="link_right_front_wheel" />
      <parent link="link_chassis"/>
      <axis rpy="0 0 0" xyz="0 1 0"/>
      <limit effort="3" velocity="0.5"/>
      <joint_properties damping="1.0" friction="1.0" />
    </joint>  
      
   <!-- ========================================================================= -->

    <!-- Left Wheel link -->
      
    <link name="link_left_front_wheel">    
      <inertial>
        <mass value="0.2"/>
        <origin rpy="0 1.5707 1.5707" xyz="0 0 0"/>
        <inertia ixx="0.00052666666" ixy="0" ixz="0" iyy="0.00052666666" iyz="0" izz="0.001"/>
      </inertial>
      
      <collision name="link_left_front_wheel_collision">
        <origin rpy="0 1.5707 1.5707" xyz="0 0 0" />
        <geometry>
          <cylinder length="0.04" radius="0.1"/>
        </geometry>
      </collision>
      
      <visual name="link_left_front_wheel_visual">
        <origin rpy="0 1.5707 1.5707" xyz="0 0 0"/>
        <geometry>
          <cylinder length="0.04" radius="0.1"/>
        </geometry>      
      </visual>
      
    </link>
      
    <!--   Joint for left wheel  -->
    <joint name="joint_left_front_wheel" type="continuous">
      <origin rpy="0 0 0" xyz="0.22 -0.18 0"/>
      <child link="link_left_front_wheel" />
      <parent link="link_chassis"/>
      <axis rpy="0 0 0" xyz="0 1 0"/>
      <limit effort="3" velocity="0.5"/>
      <joint_properties damping="1.0" friction="1.0" />
    </joint>    


   <!-- ========================================================================= -->


    <!-- Create front_wheel right -->  
      
    <link name="link_right_rear_wheel">    
      <inertial>
        <mass value="0.2"/>
        <origin rpy="0 1.5707 1.5707" xyz="0 0 0"/>
        <inertia ixx="0.00052666666" ixy="0" ixz="0" iyy="0.00052666666" iyz="0" izz="0.001"/>
      </inertial>
      
      <collision name="link_right_rear_wheel_collision">
        <origin rpy="0 1.5707 1.5707" xyz="0 0 0" />
        <geometry>
          <cylinder length="0.04" radius="0.1"/>
        </geometry>
      </collision>
      
      <visual name="link_right_rear_wheel_visual">
        <origin rpy="0 1.5707 1.5707" xyz="0 0 0"/>
        <geometry>
          <cylinder length="0.04" radius="0.1"/>
        </geometry>      
      </visual>
      
    </link>
      
    <!--   Joint for right front_wheel  -->
    <joint name="joint_right_rear_wheel" type="continuous">
      <origin rpy="0 0 0" xyz="-0.22 0.18 0"/>
      <child link="link_right_rear_wheel" />
      <parent link="link_chassis"/>
      <axis rpy="0 0 0" xyz="0 1 0"/>
      <limit effort="3" velocity="0.5"/>
      <joint_properties damping="1.0" friction="1.0" />
    </joint>  
      
   <!-- ========================================================================= -->

    <!-- Left Wheel link -->
      
    <link name="link_left_rear_wheel">    
      <inertial>
        <mass value="0.2"/>
        <origin rpy="0 1.5707 1.5707" xyz="0 0 0"/>
        <inertia ixx="0.00052666666" ixy="0" ixz="0" iyy="0.00052666666" iyz="0" izz="0.001"/>
      </inertial>
      
      <collision name="link_left_rear_wheel_collision">
        <origin rpy="0 1.5707 1.5707" xyz="0 0 0" />
        <geometry>
          <cylinder length="0.04" radius="0.1"/>
        </geometry>
      </collision>
      
      <visual name="link_left_rear_wheel_visual">
        <origin rpy="0 1.5707 1.5707" xyz="0 0 0"/>
        <geometry>
          <cylinder length="0.04" radius="0.1"/>
        </geometry>      
      </visual>
      
    </link>
      
    <!--   Joint for left wheel  -->
    <joint name="joint_left_rear_wheel" type="continuous">
      <origin rpy="0 0 0" xyz="-0.22 -0.18 0"/>
      <child link="link_left_rear_wheel" />
      <parent link="link_chassis"/>
      <axis rpy="0 0 0" xyz="0 1 0"/>
      <limit effort="3" velocity="0.5"/>
      <joint_properties damping="1.0" friction="1.0" />
    </joint>

    
  <!-- Camera -->  
    
    

    
</robot>